Traceback (most recent call last):
  File "/Users/johannes/opt/anaconda3/envs/books/lib/python3.8/site-packages/jupyter_cache/executors/utils.py", line 51, in single_nb_execution
    executenb(
  File "/Users/johannes/opt/anaconda3/envs/books/lib/python3.8/site-packages/nbclient/client.py", line 1204, in execute
    return NotebookClient(nb=nb, resources=resources, km=km, **kwargs).execute()
  File "/Users/johannes/opt/anaconda3/envs/books/lib/python3.8/site-packages/nbclient/util.py", line 84, in wrapped
    return just_run(coro(*args, **kwargs))
  File "/Users/johannes/opt/anaconda3/envs/books/lib/python3.8/site-packages/nbclient/util.py", line 62, in just_run
    return loop.run_until_complete(coro)
  File "/Users/johannes/opt/anaconda3/envs/books/lib/python3.8/asyncio/base_events.py", line 616, in run_until_complete
    return future.result()
  File "/Users/johannes/opt/anaconda3/envs/books/lib/python3.8/site-packages/nbclient/client.py", line 663, in async_execute
    await self.async_execute_cell(
  File "/Users/johannes/opt/anaconda3/envs/books/lib/python3.8/site-packages/nbclient/client.py", line 965, in async_execute_cell
    await self._check_raise_for_error(cell, cell_index, exec_reply)
  File "/Users/johannes/opt/anaconda3/envs/books/lib/python3.8/site-packages/nbclient/client.py", line 862, in _check_raise_for_error
    raise CellExecutionError.from_cell_and_msg(cell, exec_reply_content)
nbclient.exceptions.CellExecutionError: An error occurred while executing the following cell:
------------------
import numpy as np
import matplotlib.pyplot as plt
from scipy.stats import norm

import tensorflow.compat.v1.keras.backend as K # see https://stackoverflow.com/questions/61056781/typeerror-tensor-is-unhashable-instead-use-tensor-ref-as-the-key-in-keras
import tensorflow as tf
tf.compat.v1.disable_eager_execution()

from keras.layers import Input, Dense, Lambda, Layer
from keras.models import Model
from keras import backend as K
from keras import metrics
from keras.datasets import mnist
from keras import losses
from keras.utils.vis_utils import plot_model
------------------

[0;31m---------------------------------------------------------------------------[0m
[0;31mImportError[0m                               Traceback (most recent call last)
Input [0;32mIn [2][0m, in [0;36m<cell line: 5>[0;34m()[0m
[1;32m      2[0m [38;5;28;01mimport[39;00m [38;5;21;01mmatplotlib[39;00m[38;5;21;01m.[39;00m[38;5;21;01mpyplot[39;00m [38;5;28;01mas[39;00m [38;5;21;01mplt[39;00m
[1;32m      3[0m [38;5;28;01mfrom[39;00m [38;5;21;01mscipy[39;00m[38;5;21;01m.[39;00m[38;5;21;01mstats[39;00m [38;5;28;01mimport[39;00m norm
[0;32m----> 5[0m [38;5;28;01mimport[39;00m [38;5;21;01mtensorflow[39;00m[38;5;21;01m.[39;00m[38;5;21;01mcompat[39;00m[38;5;21;01m.[39;00m[38;5;21;01mv1[39;00m[38;5;21;01m.[39;00m[38;5;21;01mkeras[39;00m[38;5;21;01m.[39;00m[38;5;21;01mbackend[39;00m [38;5;28;01mas[39;00m [38;5;21;01mK[39;00m [38;5;66;03m# see https://stackoverflow.com/questions/61056781/typeerror-tensor-is-unhashable-instead-use-tensor-ref-as-the-key-in-keras[39;00m
[1;32m      6[0m [38;5;28;01mimport[39;00m [38;5;21;01mtensorflow[39;00m [38;5;28;01mas[39;00m [38;5;21;01mtf[39;00m
[1;32m      7[0m tf[38;5;241m.[39mcompat[38;5;241m.[39mv1[38;5;241m.[39mdisable_eager_execution()

File [0;32m~/opt/anaconda3/envs/books/lib/python3.8/site-packages/tensorflow/__init__.py:41[0m, in [0;36m<module>[0;34m[0m
[1;32m     38[0m [38;5;28;01mimport[39;00m [38;5;21;01msix[39;00m [38;5;28;01mas[39;00m [38;5;21;01m_six[39;00m
[1;32m     39[0m [38;5;28;01mimport[39;00m [38;5;21;01msys[39;00m [38;5;28;01mas[39;00m [38;5;21;01m_sys[39;00m
[0;32m---> 41[0m [38;5;28;01mfrom[39;00m [38;5;21;01mtensorflow[39;00m[38;5;21;01m.[39;00m[38;5;21;01mpython[39;00m[38;5;21;01m.[39;00m[38;5;21;01mtools[39;00m [38;5;28;01mimport[39;00m module_util [38;5;28;01mas[39;00m _module_util
[1;32m     42[0m [38;5;28;01mfrom[39;00m [38;5;21;01mtensorflow[39;00m[38;5;21;01m.[39;00m[38;5;21;01mpython[39;00m[38;5;21;01m.[39;00m[38;5;21;01mutil[39;00m[38;5;21;01m.[39;00m[38;5;21;01mlazy_loader[39;00m [38;5;28;01mimport[39;00m LazyLoader [38;5;28;01mas[39;00m _LazyLoader
[1;32m     44[0m [38;5;66;03m# Make sure code inside the TensorFlow codebase can use tf2.enabled() at import.[39;00m

File [0;32m~/opt/anaconda3/envs/books/lib/python3.8/site-packages/tensorflow/python/__init__.py:40[0m, in [0;36m<module>[0;34m[0m
[1;32m     31[0m [38;5;28;01mimport[39;00m [38;5;21;01mtraceback[39;00m
[1;32m     33[0m [38;5;66;03m# We aim to keep this file minimal and ideally remove completely.[39;00m
[1;32m     34[0m [38;5;66;03m# If you are adding a new file with @tf_export decorators,[39;00m
[1;32m     35[0m [38;5;66;03m# import it in modules_with_exports.py instead.[39;00m
[1;32m     36[0m 
[1;32m     37[0m [38;5;66;03m# go/tf-wildcard-import[39;00m
[1;32m     38[0m [38;5;66;03m# pylint: disable=wildcard-import,g-bad-import-order,g-import-not-at-top[39;00m
[0;32m---> 40[0m [38;5;28;01mfrom[39;00m [38;5;21;01mtensorflow[39;00m[38;5;21;01m.[39;00m[38;5;21;01mpython[39;00m[38;5;21;01m.[39;00m[38;5;21;01meager[39;00m [38;5;28;01mimport[39;00m context
[1;32m     41[0m [38;5;28;01mfrom[39;00m [38;5;21;01mtensorflow[39;00m[38;5;21;01m.[39;00m[38;5;21;01mpython[39;00m [38;5;28;01mimport[39;00m pywrap_tensorflow [38;5;28;01mas[39;00m _pywrap_tensorflow
[1;32m     43[0m [38;5;66;03m# pylint: enable=wildcard-import[39;00m
[1;32m     44[0m 
[1;32m     45[0m [38;5;66;03m# Bring in subpackages.[39;00m

File [0;32m~/opt/anaconda3/envs/books/lib/python3.8/site-packages/tensorflow/python/eager/context.py:35[0m, in [0;36m<module>[0;34m[0m
[1;32m     33[0m [38;5;28;01mfrom[39;00m [38;5;21;01mtensorflow[39;00m[38;5;21;01m.[39;00m[38;5;21;01mcore[39;00m[38;5;21;01m.[39;00m[38;5;21;01mprotobuf[39;00m [38;5;28;01mimport[39;00m config_pb2
[1;32m     34[0m [38;5;28;01mfrom[39;00m [38;5;21;01mtensorflow[39;00m[38;5;21;01m.[39;00m[38;5;21;01mcore[39;00m[38;5;21;01m.[39;00m[38;5;21;01mprotobuf[39;00m [38;5;28;01mimport[39;00m rewriter_config_pb2
[0;32m---> 35[0m [38;5;28;01mfrom[39;00m [38;5;21;01mtensorflow[39;00m[38;5;21;01m.[39;00m[38;5;21;01mpython[39;00m [38;5;28;01mimport[39;00m pywrap_tfe
[1;32m     36[0m [38;5;28;01mfrom[39;00m [38;5;21;01mtensorflow[39;00m[38;5;21;01m.[39;00m[38;5;21;01mpython[39;00m [38;5;28;01mimport[39;00m tf2
[1;32m     37[0m [38;5;28;01mfrom[39;00m [38;5;21;01mtensorflow[39;00m[38;5;21;01m.[39;00m[38;5;21;01mpython[39;00m[38;5;21;01m.[39;00m[38;5;21;01mclient[39;00m [38;5;28;01mimport[39;00m pywrap_tf_session

File [0;32m~/opt/anaconda3/envs/books/lib/python3.8/site-packages/tensorflow/python/pywrap_tfe.py:29[0m, in [0;36m<module>[0;34m[0m
[1;32m     27[0m [38;5;66;03m# pylint: disable=invalid-import-order,g-bad-import-order, wildcard-import, unused-import[39;00m
[1;32m     28[0m [38;5;28;01mfrom[39;00m [38;5;21;01mtensorflow[39;00m[38;5;21;01m.[39;00m[38;5;21;01mpython[39;00m [38;5;28;01mimport[39;00m pywrap_tensorflow
[0;32m---> 29[0m [38;5;28;01mfrom[39;00m [38;5;21;01mtensorflow[39;00m[38;5;21;01m.[39;00m[38;5;21;01mpython[39;00m[38;5;21;01m.[39;00m[38;5;21;01m_pywrap_tfe[39;00m [38;5;28;01mimport[39;00m [38;5;241m*[39m

[0;31mImportError[0m: dlopen(/Users/johannes/opt/anaconda3/envs/books/lib/python3.8/site-packages/tensorflow/python/_pywrap_tfe.so, 0x0002): Library not loaded: @rpath/_pywrap_tensorflow_internal.so
  Referenced from: /Users/johannes/opt/anaconda3/envs/books/lib/python3.8/site-packages/tensorflow/python/_pywrap_tfe.so
  Reason: tried: '/Users/johannes/opt/anaconda3/envs/books/lib/python3.8/site-packages/tensorflow/python/../../_solib_darwin_x86_64/_U_S_Stensorflow_Spython_C_Upywrap_Utfe.so___Utensorflow/_pywrap_tensorflow_internal.so' (no such file), '/Users/johannes/opt/anaconda3/envs/books/lib/python3.8/site-packages/tensorflow/python/../../_solib_darwin_x86_64/_U_S_Stensorflow_Spython_C_Upywrap_Utensorflow_Uinternal_Umacos___Utensorflow_Spython/_pywrap_tensorflow_internal.so' (no such file), '/Users/johannes/opt/anaconda3/envs/books/lib/python3.8/site-packages/tensorflow/python/_pywrap_tensorflow_internal.so' (no such file), '/Users/johannes/opt/anaconda3/envs/books/lib/python3.8/site-packages/tensorflow/python/../_pywrap_tensorflow_internal.so' (no such file), '/Users/johannes/opt/anaconda3/envs/books/lib/python3.8/site-packages/tensorflow/python/../../_solib_darwin_x86_64/_U_S_Stensorflow_Spython_C_Upywrap_Utfe.so___Utensorflow/_pywrap_tensorflow_internal.so' (no such file), '/Users/johannes/opt/anaconda3/envs/books/lib/python3.8/site-packages/tensorflow/python/../../_solib_darwin_x86_64/_U_S_Stensorflow_Spython_C_Upywrap_Utensorflow_Uinternal_Umacos___Utensorflow_Spython/_pywrap_tensorflow_internal.so' (no such file), '/Users/johannes/opt/anaconda3/envs/books/lib/python3.8/site-packages/tensorflow/python/_pywrap_tensorflow_internal.so' (no such file), '/Users/johannes/opt/anaconda3/envs/books/lib/python3.8/site-packages/tensorflow/python/../_pywrap_tensorflow_internal.so' (no such file), '/Users/johannes/opt/anaconda3/envs/books/lib/_pywrap_tensorflow_internal.so' (no such file), '/Users/johannes/opt/anaconda3/envs/books/bin/../lib/_pywrap_tensorflow_internal.so' (no such file), '/Users/johannes/opt/anaconda3/envs/books/lib/_pywrap_tensorflow_internal.so' (no such file), '/Users/johannes/opt/anaconda3/envs/books/bin/../lib/_pywrap_tensorflow_internal.so' (no such file), '/usr/local/lib/_pywrap_tensorflow_internal.so' (no such file), '/usr/lib/_pywrap_tensorflow_internal.so' (no such file)
ImportError: dlopen(/Users/johannes/opt/anaconda3/envs/books/lib/python3.8/site-packages/tensorflow/python/_pywrap_tfe.so, 0x0002): Library not loaded: @rpath/_pywrap_tensorflow_internal.so
  Referenced from: /Users/johannes/opt/anaconda3/envs/books/lib/python3.8/site-packages/tensorflow/python/_pywrap_tfe.so
  Reason: tried: '/Users/johannes/opt/anaconda3/envs/books/lib/python3.8/site-packages/tensorflow/python/../../_solib_darwin_x86_64/_U_S_Stensorflow_Spython_C_Upywrap_Utfe.so___Utensorflow/_pywrap_tensorflow_internal.so' (no such file), '/Users/johannes/opt/anaconda3/envs/books/lib/python3.8/site-packages/tensorflow/python/../../_solib_darwin_x86_64/_U_S_Stensorflow_Spython_C_Upywrap_Utensorflow_Uinternal_Umacos___Utensorflow_Spython/_pywrap_tensorflow_internal.so' (no such file), '/Users/johannes/opt/anaconda3/envs/books/lib/python3.8/site-packages/tensorflow/python/_pywrap_tensorflow_internal.so' (no such file), '/Users/johannes/opt/anaconda3/envs/books/lib/python3.8/site-packages/tensorflow/python/../_pywrap_tensorflow_internal.so' (no such file), '/Users/johannes/opt/anaconda3/envs/books/lib/python3.8/site-packages/tensorflow/python/../../_solib_darwin_x86_64/_U_S_Stensorflow_Spython_C_Upywrap_Utfe.so___Utensorflow/_pywrap_tensorflow_internal.so' (no such file), '/Users/johannes/opt/anaconda3/envs/books/lib/python3.8/site-packages/tensorflow/python/../../_solib_darwin_x86_64/_U_S_Stensorflow_Spython_C_Upywrap_Utensorflow_Uinternal_Umacos___Utensorflow_Spython/_pywrap_tensorflow_internal.so' (no such file), '/Users/johannes/opt/anaconda3/envs/books/lib/python3.8/site-packages/tensorflow/python/_pywrap_tensorflow_internal.so' (no such file), '/Users/johannes/opt/anaconda3/envs/books/lib/python3.8/site-packages/tensorflow/python/../_pywrap_tensorflow_internal.so' (no such file), '/Users/johannes/opt/anaconda3/envs/books/lib/_pywrap_tensorflow_internal.so' (no such file), '/Users/johannes/opt/anaconda3/envs/books/bin/../lib/_pywrap_tensorflow_internal.so' (no such file), '/Users/johannes/opt/anaconda3/envs/books/lib/_pywrap_tensorflow_internal.so' (no such file), '/Users/johannes/opt/anaconda3/envs/books/bin/../lib/_pywrap_tensorflow_internal.so' (no such file), '/usr/local/lib/_pywrap_tensorflow_internal.so' (no such file), '/usr/lib/_pywrap_tensorflow_internal.so' (no such file)

