Traceback (most recent call last):
  File "/Users/johannes/opt/anaconda3/envs/books/lib/python3.8/site-packages/jupyter_cache/executors/utils.py", line 51, in single_nb_execution
    executenb(
  File "/Users/johannes/opt/anaconda3/envs/books/lib/python3.8/site-packages/nbclient/client.py", line 1087, in execute
    return NotebookClient(nb=nb, resources=resources, km=km, **kwargs).execute()
  File "/Users/johannes/opt/anaconda3/envs/books/lib/python3.8/site-packages/nbclient/util.py", line 74, in wrapped
    return just_run(coro(*args, **kwargs))
  File "/Users/johannes/opt/anaconda3/envs/books/lib/python3.8/site-packages/nbclient/util.py", line 53, in just_run
    return loop.run_until_complete(coro)
  File "/Users/johannes/opt/anaconda3/envs/books/lib/python3.8/asyncio/base_events.py", line 608, in run_until_complete
    return future.result()
  File "/Users/johannes/opt/anaconda3/envs/books/lib/python3.8/site-packages/nbclient/client.py", line 540, in async_execute
    await self.async_execute_cell(
  File "/Users/johannes/opt/anaconda3/envs/books/lib/python3.8/site-packages/nbclient/client.py", line 832, in async_execute_cell
    self._check_raise_for_error(cell, exec_reply)
  File "/Users/johannes/opt/anaconda3/envs/books/lib/python3.8/site-packages/nbclient/client.py", line 740, in _check_raise_for_error
    raise CellExecutionError.from_cell_and_msg(cell, exec_reply['content'])
nbclient.exceptions.CellExecutionError: An error occurred while executing the following cell:
------------------
from PIL import Image
im = np.array(Image.open("../Data/a4weiss.jpg").convert('L'))
plt.imshow(im,cmap='Greys_r')
------------------

[0;31m---------------------------------------------------------------------------[0m
[0;31mFileNotFoundError[0m                         Traceback (most recent call last)
[0;32m<ipython-input-13-afd3ee859712>[0m in [0;36m<module>[0;34m[0m
[1;32m      1[0m [0;32mfrom[0m [0mPIL[0m [0;32mimport[0m [0mImage[0m[0;34m[0m[0;34m[0m[0m
[0;32m----> 2[0;31m [0mim[0m [0;34m=[0m [0mnp[0m[0;34m.[0m[0marray[0m[0;34m([0m[0mImage[0m[0;34m.[0m[0mopen[0m[0;34m([0m[0;34m"../Data/a4weiss.jpg"[0m[0;34m)[0m[0;34m.[0m[0mconvert[0m[0;34m([0m[0;34m'L'[0m[0;34m)[0m[0;34m)[0m[0;34m[0m[0;34m[0m[0m
[0m[1;32m      3[0m [0mplt[0m[0;34m.[0m[0mimshow[0m[0;34m([0m[0mim[0m[0;34m,[0m[0mcmap[0m[0;34m=[0m[0;34m'Greys_r'[0m[0;34m)[0m[0;34m[0m[0;34m[0m[0m

[0;32m~/opt/anaconda3/envs/books/lib/python3.8/site-packages/PIL/Image.py[0m in [0;36mopen[0;34m(fp, mode, formats)[0m
[1;32m   2902[0m [0;34m[0m[0m
[1;32m   2903[0m     [0;32mif[0m [0mfilename[0m[0;34m:[0m[0;34m[0m[0;34m[0m[0m
[0;32m-> 2904[0;31m         [0mfp[0m [0;34m=[0m [0mbuiltins[0m[0;34m.[0m[0mopen[0m[0;34m([0m[0mfilename[0m[0;34m,[0m [0;34m"rb"[0m[0;34m)[0m[0;34m[0m[0;34m[0m[0m
[0m[1;32m   2905[0m         [0mexclusive_fp[0m [0;34m=[0m [0;32mTrue[0m[0;34m[0m[0;34m[0m[0m
[1;32m   2906[0m [0;34m[0m[0m

[0;31mFileNotFoundError[0m: [Errno 2] No such file or directory: '../Data/a4weiss.jpg'
FileNotFoundError: [Errno 2] No such file or directory: '../Data/a4weiss.jpg'

