Traceback (most recent call last):
  File "/Users/johannes/opt/anaconda3/envs/books/lib/python3.8/site-packages/jupyter_cache/executors/utils.py", line 51, in single_nb_execution
    executenb(
  File "/Users/johannes/opt/anaconda3/envs/books/lib/python3.8/site-packages/nbclient/client.py", line 1087, in execute
    return NotebookClient(nb=nb, resources=resources, km=km, **kwargs).execute()
  File "/Users/johannes/opt/anaconda3/envs/books/lib/python3.8/site-packages/nbclient/util.py", line 74, in wrapped
    return just_run(coro(*args, **kwargs))
  File "/Users/johannes/opt/anaconda3/envs/books/lib/python3.8/site-packages/nbclient/util.py", line 53, in just_run
    return loop.run_until_complete(coro)
  File "/Users/johannes/opt/anaconda3/envs/books/lib/python3.8/asyncio/base_events.py", line 608, in run_until_complete
    return future.result()
  File "/Users/johannes/opt/anaconda3/envs/books/lib/python3.8/site-packages/nbclient/client.py", line 540, in async_execute
    await self.async_execute_cell(
  File "/Users/johannes/opt/anaconda3/envs/books/lib/python3.8/site-packages/nbclient/client.py", line 832, in async_execute_cell
    self._check_raise_for_error(cell, exec_reply)
  File "/Users/johannes/opt/anaconda3/envs/books/lib/python3.8/site-packages/nbclient/client.py", line 740, in _check_raise_for_error
    raise CellExecutionError.from_cell_and_msg(cell, exec_reply['content'])
nbclient.exceptions.CellExecutionError: An error occurred while executing the following cell:
------------------
# load an image in PIL format
original = load_img(filename, target_size=(224, 224))
print(type(original))
print('PIL image size',original.size)
plt.imshow(original)
plt.show()
------------------

[0;31m---------------------------------------------------------------------------[0m
[0;31mFileNotFoundError[0m                         Traceback (most recent call last)
[0;32m<ipython-input-5-3d3b443d6550>[0m in [0;36m<module>[0;34m[0m
[1;32m      1[0m [0;31m# load an image in PIL format[0m[0;34m[0m[0;34m[0m[0;34m[0m[0m
[0;32m----> 2[0;31m [0moriginal[0m [0;34m=[0m [0mload_img[0m[0;34m([0m[0mfilename[0m[0;34m,[0m [0mtarget_size[0m[0;34m=[0m[0;34m([0m[0;36m224[0m[0;34m,[0m [0;36m224[0m[0;34m)[0m[0;34m)[0m[0;34m[0m[0;34m[0m[0m
[0m[1;32m      3[0m [0mprint[0m[0;34m([0m[0mtype[0m[0;34m([0m[0moriginal[0m[0;34m)[0m[0;34m)[0m[0;34m[0m[0;34m[0m[0m
[1;32m      4[0m [0mprint[0m[0;34m([0m[0;34m'PIL image size'[0m[0;34m,[0m[0moriginal[0m[0;34m.[0m[0msize[0m[0;34m)[0m[0;34m[0m[0;34m[0m[0m
[1;32m      5[0m [0mplt[0m[0;34m.[0m[0mimshow[0m[0;34m([0m[0moriginal[0m[0;34m)[0m[0;34m[0m[0;34m[0m[0m

[0;32m~/opt/anaconda3/envs/books/lib/python3.8/site-packages/tensorflow/python/keras/preprocessing/image.py[0m in [0;36mload_img[0;34m(path, grayscale, color_mode, target_size, interpolation)[0m
[1;32m    297[0m       [0mValueError[0m[0;34m:[0m [0;32mif[0m [0minterpolation[0m [0mmethod[0m [0;32mis[0m [0;32mnot[0m [0msupported[0m[0;34m.[0m[0;34m[0m[0;34m[0m[0m
[1;32m    298[0m   """
[0;32m--> 299[0;31m   return image.load_img(path, grayscale=grayscale, color_mode=color_mode,
[0m[1;32m    300[0m                         target_size=target_size, interpolation=interpolation)
[1;32m    301[0m [0;34m[0m[0m

[0;32m~/opt/anaconda3/envs/books/lib/python3.8/site-packages/keras_preprocessing/image/utils.py[0m in [0;36mload_img[0;34m(path, grayscale, color_mode, target_size, interpolation)[0m
[1;32m    111[0m         raise ImportError('Could not import PIL.Image. '
[1;32m    112[0m                           'The use of `load_img` requires PIL.')
[0;32m--> 113[0;31m     [0;32mwith[0m [0mopen[0m[0;34m([0m[0mpath[0m[0;34m,[0m [0;34m'rb'[0m[0;34m)[0m [0;32mas[0m [0mf[0m[0;34m:[0m[0;34m[0m[0;34m[0m[0m
[0m[1;32m    114[0m         [0mimg[0m [0;34m=[0m [0mpil_image[0m[0;34m.[0m[0mopen[0m[0;34m([0m[0mio[0m[0;34m.[0m[0mBytesIO[0m[0;34m([0m[0mf[0m[0;34m.[0m[0mread[0m[0;34m([0m[0;34m)[0m[0;34m)[0m[0;34m)[0m[0;34m[0m[0;34m[0m[0m
[1;32m    115[0m         [0;32mif[0m [0mcolor_mode[0m [0;34m==[0m [0;34m'grayscale'[0m[0;34m:[0m[0;34m[0m[0;34m[0m[0m

[0;31mFileNotFoundError[0m: [Errno 2] No such file or directory: '../Data/cat.jpg'
FileNotFoundError: [Errno 2] No such file or directory: '../Data/cat.jpg'

